2019-10-10 14:49:13,143 ERROR: Exception on / [POST] [in /Users/ciscuypers/programming/webdev/flask/Projects/social/venv/lib/python3.7/site-packages/flask/app.py:1761]
Traceback (most recent call last):
  File "/Users/ciscuypers/programming/webdev/flask/Projects/social/venv/lib/python3.7/site-packages/flask/app.py", line 2292, in wsgi_app
    response = self.full_dispatch_request()
  File "/Users/ciscuypers/programming/webdev/flask/Projects/social/venv/lib/python3.7/site-packages/flask/app.py", line 1815, in full_dispatch_request
    rv = self.handle_user_exception(e)
  File "/Users/ciscuypers/programming/webdev/flask/Projects/social/venv/lib/python3.7/site-packages/flask/app.py", line 1718, in handle_user_exception
    reraise(exc_type, exc_value, tb)
  File "/Users/ciscuypers/programming/webdev/flask/Projects/social/venv/lib/python3.7/site-packages/flask/_compat.py", line 35, in reraise
    raise value
  File "/Users/ciscuypers/programming/webdev/flask/Projects/social/venv/lib/python3.7/site-packages/flask/app.py", line 1813, in full_dispatch_request
    rv = self.dispatch_request()
  File "/Users/ciscuypers/programming/webdev/flask/Projects/social/venv/lib/python3.7/site-packages/flask/app.py", line 1799, in dispatch_request
    return self.view_functions[rule.endpoint](**req.view_args)
  File "/Users/ciscuypers/programming/webdev/flask/Projects/social/venv/lib/python3.7/site-packages/flask_login/utils.py", line 228, in decorated_view
    return func(*args, **kwargs)
  File "/Users/ciscuypers/programming/webdev/flask/Projects/social/app/main/routes.py", line 35, in index
    db.session.commit()
  File "/Users/ciscuypers/programming/webdev/flask/Projects/social/venv/lib/python3.7/site-packages/sqlalchemy/orm/scoping.py", line 157, in do
    return getattr(self.registry(), name)(*args, **kwargs)
  File "/Users/ciscuypers/programming/webdev/flask/Projects/social/venv/lib/python3.7/site-packages/sqlalchemy/orm/session.py", line 906, in commit
    self.transaction.commit()
  File "/Users/ciscuypers/programming/webdev/flask/Projects/social/venv/lib/python3.7/site-packages/sqlalchemy/orm/session.py", line 468, in commit
    self.session.dispatch.after_commit(self.session)
  File "/Users/ciscuypers/programming/webdev/flask/Projects/social/venv/lib/python3.7/site-packages/sqlalchemy/event/attr.py", line 218, in __call__
    fn(*args, **kw)
  File "/Users/ciscuypers/programming/webdev/flask/Projects/social/app/models.py", line 36, in after_commit
    add_to_index(obj.__tablename__, obj)
  File "/Users/ciscuypers/programming/webdev/flask/Projects/social/app/search.py", line 24, in add_to_index
    body=payload)
  File "/Users/ciscuypers/programming/webdev/flask/Projects/social/venv/lib/python3.7/site-packages/elasticsearch/client/utils.py", line 76, in _wrapped
    return func(*args, params=params, **kwargs)
  File "/Users/ciscuypers/programming/webdev/flask/Projects/social/venv/lib/python3.7/site-packages/elasticsearch/client/__init__.py", line 300, in index
    _make_path(index, doc_type, id), params=params, body=body)
  File "/Users/ciscuypers/programming/webdev/flask/Projects/social/venv/lib/python3.7/site-packages/elasticsearch/transport.py", line 314, in perform_request
    status, headers_response, data = connection.perform_request(method, url, params, body, headers=headers, ignore=ignore, timeout=timeout)
  File "/Users/ciscuypers/programming/webdev/flask/Projects/social/venv/lib/python3.7/site-packages/elasticsearch/connection/http_urllib3.py", line 163, in perform_request
    self._raise_error(response.status, raw_data)
  File "/Users/ciscuypers/programming/webdev/flask/Projects/social/venv/lib/python3.7/site-packages/elasticsearch/connection/base.py", line 125, in _raise_error
    raise HTTP_EXCEPTIONS.get(status_code, TransportError)(status_code, error_message, additional_info)
elasticsearch.exceptions.RequestError: TransportError(400, 'illegal_argument_exception', 'Rejecting mapping update to [post] as the final mapping would have more than 1 type: [_doc, post]')
2019-10-10 14:49:20,410 INFO: Microblog startup [in /Users/ciscuypers/programming/webdev/flask/Projects/social/app/__init__.py:76]
2019-10-10 19:56:57,113 INFO: Microblog startup [in /Users/ciscuypers/programming/webdev/flask/Projects/social/app/__init__.py:76]
2019-10-10 19:57:11,998 INFO: Microblog startup [in /Users/ciscuypers/programming/webdev/flask/Projects/social/app/__init__.py:76]
2019-10-10 19:57:19,947 INFO: Microblog startup [in /Users/ciscuypers/programming/webdev/flask/Projects/social/app/__init__.py:76]
2019-10-11 12:55:30,953 INFO: Microblog startup [in /Users/ciscuypers/programming/webdev/flask/Projects/social/app/__init__.py:76]
2019-10-11 13:01:20,130 INFO: Microblog startup [in /Users/ciscuypers/programming/webdev/flask/Projects/social/app/__init__.py:76]
2019-10-11 13:03:26,949 INFO: Microblog startup [in /Users/ciscuypers/programming/webdev/flask/Projects/social/app/__init__.py:76]
2019-10-11 17:08:33,483 INFO: Microblog startup [in /Users/ciscuypers/programming/webdev/flask/Projects/social/app/__init__.py:76]
2019-10-11 17:10:02,896 INFO: Microblog startup [in /Users/ciscuypers/programming/webdev/flask/Projects/social/app/__init__.py:76]
2019-10-11 17:12:47,927 INFO: Microblog startup [in /Users/ciscuypers/programming/webdev/flask/Projects/social/app/__init__.py:76]
2019-10-11 17:12:52,201 INFO: Microblog startup [in /Users/ciscuypers/programming/webdev/flask/Projects/social/app/__init__.py:76]
2019-10-11 17:13:10,635 ERROR: Exception on /search [GET] [in /Users/ciscuypers/programming/webdev/flask/Projects/social/venv/lib/python3.7/site-packages/flask/app.py:1761]
Traceback (most recent call last):
  File "/Users/ciscuypers/programming/webdev/flask/Projects/social/venv/lib/python3.7/site-packages/flask/app.py", line 2292, in wsgi_app
    response = self.full_dispatch_request()
  File "/Users/ciscuypers/programming/webdev/flask/Projects/social/venv/lib/python3.7/site-packages/flask/app.py", line 1815, in full_dispatch_request
    rv = self.handle_user_exception(e)
  File "/Users/ciscuypers/programming/webdev/flask/Projects/social/venv/lib/python3.7/site-packages/flask/app.py", line 1718, in handle_user_exception
    reraise(exc_type, exc_value, tb)
  File "/Users/ciscuypers/programming/webdev/flask/Projects/social/venv/lib/python3.7/site-packages/flask/_compat.py", line 35, in reraise
    raise value
  File "/Users/ciscuypers/programming/webdev/flask/Projects/social/venv/lib/python3.7/site-packages/flask/app.py", line 1813, in full_dispatch_request
    rv = self.dispatch_request()
  File "/Users/ciscuypers/programming/webdev/flask/Projects/social/venv/lib/python3.7/site-packages/flask/app.py", line 1799, in dispatch_request
    return self.view_functions[rule.endpoint](**req.view_args)
  File "/Users/ciscuypers/programming/webdev/flask/Projects/social/venv/lib/python3.7/site-packages/flask_login/utils.py", line 228, in decorated_view
    return func(*args, **kwargs)
  File "/Users/ciscuypers/programming/webdev/flask/Projects/social/app/main/routes.py", line 146, in search
    if len(total) > page * current_app.config['POSTS_PER_PAGE'] else None
TypeError: object of type 'int' has no len()
2019-10-11 17:15:15,611 INFO: Microblog startup [in /Users/ciscuypers/programming/webdev/flask/Projects/social/app/__init__.py:76]
2019-10-11 17:15:21,864 ERROR: Exception on /search [GET] [in /Users/ciscuypers/programming/webdev/flask/Projects/social/venv/lib/python3.7/site-packages/flask/app.py:1761]
Traceback (most recent call last):
  File "/Users/ciscuypers/programming/webdev/flask/Projects/social/venv/lib/python3.7/site-packages/flask/app.py", line 2292, in wsgi_app
    response = self.full_dispatch_request()
  File "/Users/ciscuypers/programming/webdev/flask/Projects/social/venv/lib/python3.7/site-packages/flask/app.py", line 1816, in full_dispatch_request
    return self.finalize_request(rv)
  File "/Users/ciscuypers/programming/webdev/flask/Projects/social/venv/lib/python3.7/site-packages/flask/app.py", line 1831, in finalize_request
    response = self.make_response(rv)
  File "/Users/ciscuypers/programming/webdev/flask/Projects/social/venv/lib/python3.7/site-packages/flask/app.py", line 1957, in make_response
    'The view function did not return a valid response. The'
TypeError: The view function did not return a valid response. The function either returned None or ended without a return statement.
2019-10-11 17:15:25,693 ERROR: Exception on /search [GET] [in /Users/ciscuypers/programming/webdev/flask/Projects/social/venv/lib/python3.7/site-packages/flask/app.py:1761]
Traceback (most recent call last):
  File "/Users/ciscuypers/programming/webdev/flask/Projects/social/venv/lib/python3.7/site-packages/flask/app.py", line 2292, in wsgi_app
    response = self.full_dispatch_request()
  File "/Users/ciscuypers/programming/webdev/flask/Projects/social/venv/lib/python3.7/site-packages/flask/app.py", line 1816, in full_dispatch_request
    return self.finalize_request(rv)
  File "/Users/ciscuypers/programming/webdev/flask/Projects/social/venv/lib/python3.7/site-packages/flask/app.py", line 1831, in finalize_request
    response = self.make_response(rv)
  File "/Users/ciscuypers/programming/webdev/flask/Projects/social/venv/lib/python3.7/site-packages/flask/app.py", line 1957, in make_response
    'The view function did not return a valid response. The'
TypeError: The view function did not return a valid response. The function either returned None or ended without a return statement.
2019-10-11 17:15:42,248 INFO: Microblog startup [in /Users/ciscuypers/programming/webdev/flask/Projects/social/app/__init__.py:76]
