2019-10-09 21:46:24,990 ERROR: Exception on /search [GET] [in /Users/ciscuypers/programming/webdev/flask/Projects/social/venv/lib/python3.7/site-packages/flask/app.py:1761]
Traceback (most recent call last):
  File "/Users/ciscuypers/programming/webdev/flask/Projects/social/venv/lib/python3.7/site-packages/sqlalchemy/sql/elements.py", line 666, in comparator
    comparator_factory = self.type.comparator_factory
AttributeError: 'NoneType' object has no attribute 'comparator_factory'

During handling of the above exception, another exception occurred:

Traceback (most recent call last):
  File "/Users/ciscuypers/programming/webdev/flask/Projects/social/venv/lib/python3.7/site-packages/flask/app.py", line 2292, in wsgi_app
    response = self.full_dispatch_request()
  File "/Users/ciscuypers/programming/webdev/flask/Projects/social/venv/lib/python3.7/site-packages/flask/app.py", line 1815, in full_dispatch_request
    rv = self.handle_user_exception(e)
  File "/Users/ciscuypers/programming/webdev/flask/Projects/social/venv/lib/python3.7/site-packages/flask/app.py", line 1718, in handle_user_exception
    reraise(exc_type, exc_value, tb)
  File "/Users/ciscuypers/programming/webdev/flask/Projects/social/venv/lib/python3.7/site-packages/flask/_compat.py", line 35, in reraise
    raise value
  File "/Users/ciscuypers/programming/webdev/flask/Projects/social/venv/lib/python3.7/site-packages/flask/app.py", line 1813, in full_dispatch_request
    rv = self.dispatch_request()
  File "/Users/ciscuypers/programming/webdev/flask/Projects/social/venv/lib/python3.7/site-packages/flask/app.py", line 1799, in dispatch_request
    return self.view_functions[rule.endpoint](**req.view_args)
  File "/Users/ciscuypers/programming/webdev/flask/Projects/social/venv/lib/python3.7/site-packages/flask_login/utils.py", line 228, in decorated_view
    return func(*args, **kwargs)
  File "/Users/ciscuypers/programming/webdev/flask/Projects/social/app/main/routes.py", line 143, in search
    current_app.config['POSTS_PER_PAGE'])
  File "/Users/ciscuypers/programming/webdev/flask/Projects/social/app/models.py", line 22, in search
    db.case(when, value=cls.id)), total
  File "<string>", line 2, in order_by
  File "/Users/ciscuypers/programming/webdev/flask/Projects/social/venv/lib/python3.7/site-packages/sqlalchemy/orm/base.py", line 201, in generate
    fn(self, *args[1:], **kw)
  File "/Users/ciscuypers/programming/webdev/flask/Projects/social/venv/lib/python3.7/site-packages/sqlalchemy/orm/query.py", line 1589, in order_by
    criterion = self._adapt_col_list(criterion)
  File "/Users/ciscuypers/programming/webdev/flask/Projects/social/venv/lib/python3.7/site-packages/sqlalchemy/orm/query.py", line 256, in _adapt_col_list
    for o in cols
  File "/Users/ciscuypers/programming/webdev/flask/Projects/social/venv/lib/python3.7/site-packages/sqlalchemy/orm/query.py", line 256, in <listcomp>
    for o in cols
  File "/Users/ciscuypers/programming/webdev/flask/Projects/social/venv/lib/python3.7/site-packages/sqlalchemy/sql/elements.py", line 4188, in _literal_as_label_reference
    elif hasattr(element, '__clause_element__'):
  File "/Users/ciscuypers/programming/webdev/flask/Projects/social/venv/lib/python3.7/site-packages/sqlalchemy/sql/elements.py", line 676, in __getattr__
    return getattr(self.comparator, key)
  File "/Users/ciscuypers/programming/webdev/flask/Projects/social/venv/lib/python3.7/site-packages/sqlalchemy/util/langhelpers.py", line 764, in __get__
    obj.__dict__[self.__name__] = result = self.fget(obj)
  File "/Users/ciscuypers/programming/webdev/flask/Projects/social/venv/lib/python3.7/site-packages/sqlalchemy/sql/elements.py", line 670, in comparator
    "is not a TypeEngine class or object" % self.type)
TypeError: Object None associated with '.type' attribute is not a TypeEngine class or object
2019-10-10 08:38:24,731 INFO: Microblog startup [in /Users/ciscuypers/programming/webdev/flask/Projects/social/app/__init__.py:76]
2019-10-10 14:12:24,390 INFO: Microblog startup [in /Users/ciscuypers/programming/webdev/flask/Projects/social/app/__init__.py:76]
2019-10-10 14:12:53,429 ERROR: Exception on /edit_profile [POST] [in /Users/ciscuypers/programming/webdev/flask/Projects/social/venv/lib/python3.7/site-packages/flask/app.py:1761]
Traceback (most recent call last):
  File "/Users/ciscuypers/programming/webdev/flask/Projects/social/venv/lib/python3.7/site-packages/flask/app.py", line 2292, in wsgi_app
    response = self.full_dispatch_request()
  File "/Users/ciscuypers/programming/webdev/flask/Projects/social/venv/lib/python3.7/site-packages/flask/app.py", line 1815, in full_dispatch_request
    rv = self.handle_user_exception(e)
  File "/Users/ciscuypers/programming/webdev/flask/Projects/social/venv/lib/python3.7/site-packages/flask/app.py", line 1718, in handle_user_exception
    reraise(exc_type, exc_value, tb)
  File "/Users/ciscuypers/programming/webdev/flask/Projects/social/venv/lib/python3.7/site-packages/flask/_compat.py", line 35, in reraise
    raise value
  File "/Users/ciscuypers/programming/webdev/flask/Projects/social/venv/lib/python3.7/site-packages/flask/app.py", line 1813, in full_dispatch_request
    rv = self.dispatch_request()
  File "/Users/ciscuypers/programming/webdev/flask/Projects/social/venv/lib/python3.7/site-packages/flask/app.py", line 1799, in dispatch_request
    return self.view_functions[rule.endpoint](**req.view_args)
  File "/Users/ciscuypers/programming/webdev/flask/Projects/social/venv/lib/python3.7/site-packages/flask_login/utils.py", line 228, in decorated_view
    return func(*args, **kwargs)
  File "/Users/ciscuypers/programming/webdev/flask/Projects/social/app/main/routes.py", line 89, in edit_profile
    return redirect(url_for('edit_profile'))
  File "/Users/ciscuypers/programming/webdev/flask/Projects/social/venv/lib/python3.7/site-packages/flask/helpers.py", line 356, in url_for
    return appctx.app.handle_url_build_error(error, endpoint, values)
  File "/Users/ciscuypers/programming/webdev/flask/Projects/social/venv/lib/python3.7/site-packages/flask/app.py", line 2061, in handle_url_build_error
    reraise(exc_type, exc_value, tb)
  File "/Users/ciscuypers/programming/webdev/flask/Projects/social/venv/lib/python3.7/site-packages/flask/_compat.py", line 35, in reraise
    raise value
  File "/Users/ciscuypers/programming/webdev/flask/Projects/social/venv/lib/python3.7/site-packages/flask/helpers.py", line 345, in url_for
    force_external=external)
  File "/Users/ciscuypers/programming/webdev/flask/Projects/social/venv/lib/python3.7/site-packages/werkzeug/routing.py", line 1776, in build
    raise BuildError(endpoint, values, method, self)
werkzeug.routing.BuildError: Could not build url for endpoint 'edit_profile'. Did you mean 'main.edit_profile' instead?
2019-10-10 14:16:15,041 INFO: Microblog startup [in /Users/ciscuypers/programming/webdev/flask/Projects/social/app/__init__.py:76]
