2019-08-22 22:24:12,144 ERROR: Exception on /auth/login [POST] [in /Users/ciscuypers 1/Documents/Learning/Programming/udacity/fullstack-nanodegree-vm/vagrant/personal_site/ciscuypers_be/flask/venv/lib/python3.7/site-packages/flask/app.py:1891]
Traceback (most recent call last):
  File "/Users/ciscuypers 1/Documents/Learning/Programming/udacity/fullstack-nanodegree-vm/vagrant/personal_site/ciscuypers_be/flask/venv/lib/python3.7/site-packages/sqlalchemy/engine/base.py", line 1244, in _execute_context
    cursor, statement, parameters, context
  File "/Users/ciscuypers 1/Documents/Learning/Programming/udacity/fullstack-nanodegree-vm/vagrant/personal_site/ciscuypers_be/flask/venv/lib/python3.7/site-packages/sqlalchemy/engine/default.py", line 552, in do_execute
    cursor.execute(statement, parameters)
sqlite3.DatabaseError: database disk image is malformed

The above exception was the direct cause of the following exception:

Traceback (most recent call last):
  File "/Users/ciscuypers 1/Documents/Learning/Programming/udacity/fullstack-nanodegree-vm/vagrant/personal_site/ciscuypers_be/flask/venv/lib/python3.7/site-packages/flask/app.py", line 2446, in wsgi_app
    response = self.full_dispatch_request()
  File "/Users/ciscuypers 1/Documents/Learning/Programming/udacity/fullstack-nanodegree-vm/vagrant/personal_site/ciscuypers_be/flask/venv/lib/python3.7/site-packages/flask/app.py", line 1951, in full_dispatch_request
    rv = self.handle_user_exception(e)
  File "/Users/ciscuypers 1/Documents/Learning/Programming/udacity/fullstack-nanodegree-vm/vagrant/personal_site/ciscuypers_be/flask/venv/lib/python3.7/site-packages/flask/app.py", line 1820, in handle_user_exception
    reraise(exc_type, exc_value, tb)
  File "/Users/ciscuypers 1/Documents/Learning/Programming/udacity/fullstack-nanodegree-vm/vagrant/personal_site/ciscuypers_be/flask/venv/lib/python3.7/site-packages/flask/_compat.py", line 39, in reraise
    raise value
  File "/Users/ciscuypers 1/Documents/Learning/Programming/udacity/fullstack-nanodegree-vm/vagrant/personal_site/ciscuypers_be/flask/venv/lib/python3.7/site-packages/flask/app.py", line 1949, in full_dispatch_request
    rv = self.dispatch_request()
  File "/Users/ciscuypers 1/Documents/Learning/Programming/udacity/fullstack-nanodegree-vm/vagrant/personal_site/ciscuypers_be/flask/venv/lib/python3.7/site-packages/flask/app.py", line 1935, in dispatch_request
    return self.view_functions[rule.endpoint](**req.view_args)
  File "/Users/ciscuypers 1/Documents/Learning/Programming/complete_flask/microblog/app/auth/routes.py", line 21, in login
    user = User.query.filter_by(username=form.username.data).first()
  File "/Users/ciscuypers 1/Documents/Learning/Programming/udacity/fullstack-nanodegree-vm/vagrant/personal_site/ciscuypers_be/flask/venv/lib/python3.7/site-packages/sqlalchemy/orm/query.py", line 3228, in first
    ret = list(self[0:1])
  File "/Users/ciscuypers 1/Documents/Learning/Programming/udacity/fullstack-nanodegree-vm/vagrant/personal_site/ciscuypers_be/flask/venv/lib/python3.7/site-packages/sqlalchemy/orm/query.py", line 3018, in __getitem__
    return list(res)
  File "/Users/ciscuypers 1/Documents/Learning/Programming/udacity/fullstack-nanodegree-vm/vagrant/personal_site/ciscuypers_be/flask/venv/lib/python3.7/site-packages/sqlalchemy/orm/query.py", line 3330, in __iter__
    return self._execute_and_instances(context)
  File "/Users/ciscuypers 1/Documents/Learning/Programming/udacity/fullstack-nanodegree-vm/vagrant/personal_site/ciscuypers_be/flask/venv/lib/python3.7/site-packages/sqlalchemy/orm/query.py", line 3355, in _execute_and_instances
    result = conn.execute(querycontext.statement, self._params)
  File "/Users/ciscuypers 1/Documents/Learning/Programming/udacity/fullstack-nanodegree-vm/vagrant/personal_site/ciscuypers_be/flask/venv/lib/python3.7/site-packages/sqlalchemy/engine/base.py", line 988, in execute
    return meth(self, multiparams, params)
  File "/Users/ciscuypers 1/Documents/Learning/Programming/udacity/fullstack-nanodegree-vm/vagrant/personal_site/ciscuypers_be/flask/venv/lib/python3.7/site-packages/sqlalchemy/sql/elements.py", line 287, in _execute_on_connection
    return connection._execute_clauseelement(self, multiparams, params)
  File "/Users/ciscuypers 1/Documents/Learning/Programming/udacity/fullstack-nanodegree-vm/vagrant/personal_site/ciscuypers_be/flask/venv/lib/python3.7/site-packages/sqlalchemy/engine/base.py", line 1107, in _execute_clauseelement
    distilled_params,
  File "/Users/ciscuypers 1/Documents/Learning/Programming/udacity/fullstack-nanodegree-vm/vagrant/personal_site/ciscuypers_be/flask/venv/lib/python3.7/site-packages/sqlalchemy/engine/base.py", line 1248, in _execute_context
    e, statement, parameters, cursor, context
  File "/Users/ciscuypers 1/Documents/Learning/Programming/udacity/fullstack-nanodegree-vm/vagrant/personal_site/ciscuypers_be/flask/venv/lib/python3.7/site-packages/sqlalchemy/engine/base.py", line 1466, in _handle_dbapi_exception
    util.raise_from_cause(sqlalchemy_exception, exc_info)
  File "/Users/ciscuypers 1/Documents/Learning/Programming/udacity/fullstack-nanodegree-vm/vagrant/personal_site/ciscuypers_be/flask/venv/lib/python3.7/site-packages/sqlalchemy/util/compat.py", line 398, in raise_from_cause
    reraise(type(exception), exception, tb=exc_tb, cause=cause)
  File "/Users/ciscuypers 1/Documents/Learning/Programming/udacity/fullstack-nanodegree-vm/vagrant/personal_site/ciscuypers_be/flask/venv/lib/python3.7/site-packages/sqlalchemy/util/compat.py", line 152, in reraise
    raise value.with_traceback(tb)
  File "/Users/ciscuypers 1/Documents/Learning/Programming/udacity/fullstack-nanodegree-vm/vagrant/personal_site/ciscuypers_be/flask/venv/lib/python3.7/site-packages/sqlalchemy/engine/base.py", line 1244, in _execute_context
    cursor, statement, parameters, context
  File "/Users/ciscuypers 1/Documents/Learning/Programming/udacity/fullstack-nanodegree-vm/vagrant/personal_site/ciscuypers_be/flask/venv/lib/python3.7/site-packages/sqlalchemy/engine/default.py", line 552, in do_execute
    cursor.execute(statement, parameters)
sqlalchemy.exc.DatabaseError: (sqlite3.DatabaseError) database disk image is malformed
[SQL: SELECT user.id AS user_id, user.username AS user_username, user.email AS user_email, user.password_hash AS user_password_hash, user.about_me AS user_about_me, user.last_seen AS user_last_seen 
FROM user 
WHERE user.username = ?
 LIMIT ? OFFSET ?]
[parameters: ('Cis', 1, 0)]
(Background on this error at: http://sqlalche.me/e/4xp6)
